Workbook

Sheet README
A1: How to use this model
A3: 1. Pick a scenario in Assumptions!F3 (1 Conservative, 2 Base, 3 Aggressive).
A4: 2. Blue cells are inputs; yellow cells are key levers. Black cells are formulas - don't overwrite them.
A5: 3. Summary shows setup cost, capital required, break-even, unit economics, pricing.
A6: 4. Pricing compares each plan's price with the commission the subscriber expects to earn and the analyst time saved.
A7: 5. UnitCosts derives Claude AI cost per deal from token volumes and list prices.
A8: 6. Infrastructure itemizes the AWS servers defined in infra/terraform.
A9: All figures are planning estimates, not quotes. Validate the starred growth and churn assumptions with beta customers.

Sheet Summary
A1: LendAgent - business model summary
A2: Change inputs on Assumptions / Pricing / UnitCosts / Infrastructure / Staffing / Setup.
A3: Scenario shown | C3: =Assumptions!$G$3 -> Base | D3: =IF(Assumptions!$F$34=1,"Full team","Lean team") -> Full team
A5: Cost to set up the business
A6: One-time setup costs (legal, SOC 2, pen test, brand, equipment) | C6: =Setup!$C$18 -> 211600
A7: Pre-launch burn: all costs before first paid month | C7: =SUMPRODUCT((Monthly!$C$4:$AL$4<Assumptions!$F$7)*Monthly!$C$40:$AL$40) -> 739250
A8: Peak operating capital needed (salaries, servers, marketing until profitable; no loan funding) | C8: =MAX(0,-MIN(Monthly!$C$39:$AL$39)) -> 3125494.2
A9: Month of peak capital need | C9: =INDEX(Monthly!$C$4:$AL$4,MATCH(MIN(Monthly!$C$39:$AL$39),Monthly!$C$39:$AL$39,0)) -> 29
A10: Recommended funding for the business (peak need + 25% cushion) | C10: =C8*1.25 -> 3906867.8
A11: Monthly run-rate costs
A12: Servers / hosting baseline per month (production) | C12: =Infrastructure!$C$18 -> 2950
A13: Security & operations SaaS per month | C13: =Infrastructure!$C$28 -> 3800
A14: Total costs in month 12 | C14: =INDEX(Monthly!$C$40:$AL$40,12) -> 181803.6
A15: Total costs in month 36 | C15: =INDEX(Monthly!$C$40:$AL$40,36) -> 655284.51
A16: Unit economics (per account per month)
A17: Blended price per account (ARPA) | C17: =Pricing!$C$26 -> 1424
A18: AI + OCR + hosting variable cost per account | C18: =Pricing!$C$27*(Assumptions!$F$18*(UnitCosts!$C$36+UnitCosts!$C$28)+UnitCosts!$C$37+Assumptions!$F$27)+Assumptions!$F$28 -> 238.65175
A19: Claude AI cost per deal analyzed | C19: =UnitCosts!$C$36 -> 5.521875
A20: Contribution after variable costs and card fees | C20: =C17*(1-Assumptions!$F$26)-C18 -> 1144.0522
A21: Customer lifetime (months) = 1 / churn | C21: =1/Assumptions!$F$12 -> 40
A22: Lifetime value (LTV) | C22: =C20*C21 -> 45762.09
A23: Customer acquisition cost (CAC) | C23: =Assumptions!$F$21 -> 4000
A24: LTV / CAC | C24: =IFERROR(C22/C23,0) -> 11.440523
A25: CAC payback (months) | C25: =IFERROR(C23/C20,0) -> 3.4963438
A26: Milestones
A27: First month with positive EBITDA | C27: =IF(MIN(Monthly!$C$42:$AL$42)=999,"Beyond month 36",MIN(Monthly!$C$42:$AL$42)) -> 30
A28: Month cumulative cash turns positive | C28: =IF(MIN(Monthly!$C$43:$AL$43)=999,"Beyond month 36",MIN(Monthly!$C$43:$AL$43)) -> Beyond month 36
A29: Paying accounts - month 12 | C29: =INDEX(Monthly!$C$11:$AL$11,12) -> 41.588916
A30: Paying accounts - month 24 | C30: =INDEX(Monthly!$C$11:$AL$11,24) -> 192.11592
A31: Paying accounts - month 36 | C31: =INDEX(Monthly!$C$11:$AL$11,36) -> 548.27272
A32: Annual recurring revenue (ARR) - month 36 | C32: =INDEX(Monthly!$C$14:$AL$14,36)*12 -> 9368884.2
A33: Annual results
A34: Revenue - Year 1 | C34: =SUMIF(Monthly!$C$5:$AL$5,1,Monthly!$C$16:$AL$16) -> 222754.05
A35: Revenue - Year 2 | C35: =SUMIF(Monthly!$C$5:$AL$5,2,Monthly!$C$16:$AL$16) -> 2036095.1
A36: Revenue - Year 3 | C36: =SUMIF(Monthly!$C$5:$AL$5,3,Monthly!$C$16:$AL$16) -> 6398774.4
A37: EBITDA - Year 1 | C37: =SUMIF(Monthly!$C$5:$AL$5,1,Monthly!$C$38:$AL$38) -> -1507608.4
A38: EBITDA - Year 2 | C38: =SUMIF(Monthly!$C$5:$AL$5,2,Monthly!$C$38:$AL$38) -> -1431517.6
A39: EBITDA - Year 3 | C39: =SUMIF(Monthly!$C$5:$AL$5,3,Monthly!$C$38:$AL$38) -> 386178.16
A40: Gross margin - Year 3 | C40: =IFERROR(SUMIF(Monthly!$C$5:$AL$5,3,Monthly!$C$25:$AL$25)/SUMIF(Monthly!$C$5:$AL$5,3,Monthly!$C$16:$AL$16),0) -> 0.69978548
A41: Pricing check
...

Sheet Assumptions
A1: Assumptions
A2: Blue = input you can change. Yellow = scenario selector. Column F feeds the model.
A3: Scenario (1 = Conservative, 2 = Base, 3 = Aggressive) | F3: 2 | G3: =CHOOSE($F$3,"Conservative","Base","Aggressive") -> Base
A5: Assumption | C5: Conservative | D5: Base | E5: Aggressive | F5: Selected | G5: Source / note
A6: Timing
A7: First paid month (earlier months = build + private beta) | C7: 8 | D7: 7 | E7: 6 | F7: =CHOOSE($F$3,C7,D7,E7) -> 7 | G7: Plan: 6-month MVP build incl. SOC 2 Type I readiness; see PLAN.md roadmap.
A8: Customer growth
A9: New paying accounts in launch month | C9: 4 | D9: 6 | E9: 10 | F9: =CHOOSE($F$3,C9,D9,E9) -> 6 | G9: Founder-led sales from beta waitlist; assumption to validate in beta.
A10: Monthly growth in new-account adds | C10: 0.05 | D10: 0.08 | E10: 0.1 | F10: =CHOOSE($F$3,C10,D10,E10) -> 0.08 | G10: Assumption. Typical early vertical SaaS 5-12%/mo.
A11: Cap on new accounts per month | C11: 50 | D11: 90 | E11: 150 | F11: =CHOOSE($F$3,C11,D11,E11) -> 90 | G11: Sales/onboarding capacity ceiling.
A12: Monthly account churn | C12: 0.035 | D12: 0.025 | E12: 0.018 | F12: =CHOOSE($F$3,C12,D12,E12) -> 0.025 | G12: Assumption. SMB vertical SaaS commonly 2-4%/mo.
A13: Plan mix (share of new accounts)
A14: Solo Broker plan share | C14: 0.5 | D14: 0.45 | E14: 0.4 | F14: =CHOOSE($F$3,C14,D14,E14) -> 0.45 | G14: Assumption.
A15: Broker Team plan share | C15: 0.38 | D15: 0.4 | E15: 0.42 | F15: =CHOOSE($F$3,C15,D15,E15) -> 0.4 | G15: Assumption.
A16: Brokerage Firm plan share | C16: 0.12 | D16: 0.15 | E16: 0.18 | F16: =CHOOSE($F$3,C16,D16,E16) -> 0.15 | G16: Assumption. Shares must total 100%.
A17: Usage
A18: Deals analyzed per seat per month | C18: 10 | D18: 8 | E18: 8 | F18: =CHOOSE($F$3,C18,D18,E18) -> 8 | G18: Assumption: pipeline deals worked (not closed). Higher usage = higher AI cost.
A19: Support & acquisition
A20: Accounts per customer-success/support rep | C20: 50 | D20: 60 | E20: 75 | F20: =CHOOSE($F$3,C20,D20,E20) -> 60 | G20: Assumption for high-touch B2B onboarding.
A21: Customer acquisition cost per new account ($) | C21: 6000 | D21: 4000 | E21: 2500 | F21: =CHOOSE($F$3,C21,D21,E21) -> 4000 | G21: Assumption: paid search/LinkedIn, events, referral fees. AE and marketing salaries are in Staffing, so fully loaded CAC is higher. Validate after launch.
A23: Costs (all scenarios)
A24: Customer success rep, loaded monthly cost ($) | F24: 8500 | G24: ~$80k salary x 1.25 burden / 12.
A25: Base marketing spend per month ($), from 2 months pre-launch | F25: 5000 | G25: Content, website, broker conferences and associations (e.g. AACFB, state broker groups).
A26: Card/ACH processing as % of revenue | F26: 0.029 | G26: Stripe list price 2.9% + $0.30 (ACH cheaper).
A27: Variable hosting per seat per month ($) | F27: 12 | G27: Storage, egress, worker compute, embeddings. Estimate.
A28: Per-tenant encryption key per account per month ($) | F28: 1 | G28: AWS KMS customer-managed key $1/key/month.
A29: Hosting during build as % of production baseline | F29: 0.4 | G29: Staging + small prod before launch.
A30: Insurance per month: cyber, tech E&O, D&O ($) | F30: 2500 | G30: Estimate; quotes vary with limits ($3-5M cyber/E&O typical for fintech vendors).
A31: Accounting, bookkeeping, legal retainer per month ($) | F31: 4500 | G31: Estimate.
A32: SOC 2 Type II + annual pen test + audits, per month ($) | F32: 5000 | G32: ~$60k/yr once on annual SOC 2 Type II cycle.
A33: Month recurring compliance costs begin | F33: 13 | G33: After Type I.
A34: Team plan: 1 = Full team, 2 = Lean founder-led team (see Staffing) | F34: 1 | G34: Lean = founder unpaid in year 1, fractional SME/security, later hires.
A35: Other G&A per month ($): software seats, travel, co-working | F35: 3000 | G35: Estimate.
A37: Check: plan mix totals 100% | F37: =Assumptions!$F$14+Assumptions!$F$15+Assumptions!$F$16 -> 1

Sheet Pricing
A1: Pricing vs. subscriber commission
A2: Value-based check: what each tier costs relative to the commission it helps close and the analyst time it saves.
A4: Per account, per month | C4: Solo Broker | D4: Broker Team | E4: Brokerage Firm
A5: Target subscriber | C5: Independent commercial loan broker | D5: Broker with 2-3 partners or analysts | E5: Commercial brokerage firm (up to 10 brokers)
A6: Seats included | C6: 1 | D6: 3 | E6: 10
A7: Average loan size ($) | C7: 1500000 | D7: 2000000 | E7: 2500000
A8: Broker fee / commission (% of loan) | C8: 0.01 | D8: 0.01 | E8: 0.01
A9: Loans closed per month | C9: 1.5 | D9: 4 | E9: 8
A10: Expected commission per month ($) | C10: =C7*C8*C9 -> 22500 | D10: =D7*D8*D9 -> 80000 | E10: =E7*E8*E9 -> 200000
A11: Deals analyzed per seat per month | C11: =Assumptions!$F$18 -> 8 | D11: =Assumptions!$F$18 -> 8 | E11: =Assumptions!$F$18 -> 8
A12: Analyst hours saved per deal analyzed | C12: 6 | D12: 6 | E12: 6
A13: Value of broker/analyst time per hour ($) | C13: 75 | D13: 75 | E13: 75
A14: Value of time saved per month ($) | C14: =C6*C11*C12*C13 -> 3600 | D14: =D6*D11*D12*D13 -> 10800 | E14: =E6*E11*E12*E13 -> 36000
A15: Recommended list price per month ($) | C15: 499 | D15: 1499 | E15: 3999
A16: Price as % of expected commission | C16: =IFERROR(C15/C10,0) -> 0.022177778 | D16: =IFERROR(D15/D10,0) -> 0.0187375 | E16: =IFERROR(E15/E10,0) -> 0.019995
A17: Customer ROI on time saved alone | C17: =IFERROR(C14/C15,0) -> 7.2144289 | D17: =IFERROR(D14/D15,0) -> 7.2048032 | E17: =IFERROR(E14/E15,0) -> 9.0022506
A18: Value-based ceiling at target share ($) | C18: =C10*$C$23 -> 675 | D18: =D10*$C$23 -> 2400 | E18: =E10*$C$23 -> 6000
A19: One-time onboarding fee ($) | C19: 0 | D19: 500 | E19: 2500
A20: Plan mix (from Assumptions) | C20: =Assumptions!$F$14 -> 0.45 | D20: =Assumptions!$F$15 -> 0.4 | E20: =Assumptions!$F$16 -> 0.15
A23: Target price as share of commission (value-based ceiling) | C23: 0.03
A25: Blended (by plan mix)
A26: Blended revenue per account per month (ARPA) ($) | C26: =SUMPRODUCT(C15:E15,C20:E20) -> 1424
A27: Blended seats per account | C27: =SUMPRODUCT(C6:E6,C20:E20) -> 3.15
A28: Blended onboarding fee per new account ($) | C28: =SUMPRODUCT(C19:E19,C20:E20) -> 575
A30: Why flat subscriptions, not a % of commission: taking a share of loan fees can make the platform look like a broker/finder under some state lending laws (e.g. California Financing Law) - confirm with regulatory counsel before offering any success-fee plan.

Sheet UnitCosts
A1: AI and document-processing unit costs
A2: Claude API list prices (USD per million tokens), Anthropic first-party, Oct 2026. Bedrock pricing may differ.
A4: Model prices ($ per 1M tokens)
A5: Claude Opus 5.5 - input | C5: 4
A6: Claude Opus 5.5 - output | C6: 20
A7: Claude Opus 5.5 - cache read | C7: 0.2
A8: Claude Sonnet 5.5 - input | C8: 2
A9: Claude Sonnet 5.5 - output | C9: 10
A10: Claude Sonnet 5.5 - cache read | C10: 0.2
A11: Claude Haiku 5.5 - input (prompts <=100K) | C11: 0.1
A12: Claude Haiku 5.5 - output (prompts <=100K) | C12: 0.5
A13: Cache write premium (x input price) | C13: 1.25
A14: Per deal: document extraction (Haiku 5.5)
A15: Pages per loan package | C15: 250
A16: Tokens per page | C16: 1500
A17: Structured output tokens per deal | C17: 40000
A18: Extraction cost per deal ($) | C18: =$C$15*$C$16/1000000*$C$11+$C$17/1000000*$C$12 -> 0.0575
A19: Per deal: underwriting analysis, workbook and memo (Opus 5.5)
A20: Agent turns per deal | C20: 25
A21: Average context per turn (tokens) | C21: 120000
A22: Share of input served from prompt cache | C22: 0.85
A23: Output + thinking tokens per deal | C23: 80000
A24: Analysis cost per deal ($) | C24: =$C$20*$C$21/1000000*($C$22*$C$7+(1-$C$22)*$C$5*$C$13)+$C$23/1000000*$C$6 -> 4.36
A25: Per deal: OCR for scanned pages (AWS Textract)
A26: Share of pages needing OCR | C26: 0.4
A27: OCR price per page ($) | C27: 0.015
A28: OCR cost per deal ($) | C28: =$C$15*$C$26*$C$27 -> 1.5
A29: Per seat: everyday assistant work (Sonnet 5.5)
A30: Assistant sessions per seat per month | C30: 80
A31: Input tokens per session | C31: 60000
A32: Output tokens per session | C32: 4000
A33: Assistant cost per seat per month ($) | C33: =$C$30*($C$31/1000000*($C$22*$C$10+(1-$C$22)*$C$8*$C$13)+$C$32/1000000*$C$9) -> 5.816
A34: Overheads
A35: Buffer for retries, evals, long documents | C35: 0.25
A36: AI cost per deal incl. buffer ($) | C36: =($C$18+$C$24)*(1+$C$35) -> 5.521875
A37: AI assistant cost per seat incl. buffer ($) | C37: =$C$33*(1+$C$35) -> 7.27

Sheet Infrastructure
A1: Remote servers and operations tooling (monthly, production baseline)
A2: AWS us-east-1 primary, us-west-2 DR. Matches infra/terraform. Estimates at list price.
A4: AWS line item | C4: $ / month | D4: Note
A5: ECS Fargate - API (3 x 1 vCPU / 2 GB, ARM) | C5: 90 | D5: Graviton Fargate ~$30/task-month.
A6: ECS Fargate - workers (4 x 2 vCPU / 4 GB, ARM) | C6: 240 | D6: Autoscale 4-20 tasks.
A7: RDS PostgreSQL Multi-AZ db.r6g.large + 200 GB gp3 | C7: 420 | D7: Encrypted, 35-day PITR.
A8: NAT gateways (3 AZ) + data processing | C8: 150 | D8: $0.045/hr each + $0.045/GB.
A9: Interface VPC endpoints (8 services x 3 AZ) | C9: 180 | D9: ~$7.30 per endpoint per AZ.
A10: Application Load Balancer + WAF | C10: 90 | D10: WAF $5/ACL + $1/rule + requests.
A11: S3 documents + DR replica + audit (Object Lock) | C11: 120 | D11: Grows with tenants.
A12: KMS platform keys + API requests | C12: 40 | D12: Per-tenant keys are in variable costs.
A13: CloudTrail data events, GuardDuty, Security Hub, Inspector | C13: 350 | D13: Security monitoring.
A14: CloudWatch logs and metrics (400-day retention) | C14: 250
A15: AWS Backup + cross-region RDS backup copies | C15: 120 | D15: DR region us-west-2.
A16: Staging environment (2 AZ, single-AZ DB) | C16: 600
A17: AWS Business Support | C17: 300 | D17: Greater of $100 or ~10% of spend.
A18: Hosting baseline total | C18: =SUM(C5:C17) -> 2950
A20: Security and operations SaaS
A21: Compliance automation (Vanta / Drata) | C21: 1000 | D21: ~$12k/yr.
A22: Observability / SIEM (e.g. Datadog) | C22: 900
A23: Single sign-on (e.g. WorkOS) for brokerage-firm accounts | C23: 500
A24: Support desk + in-app chat (Intercom / Zendesk) | C24: 400
A25: Source control, CI/CD, code + dependency scanning | C25: 400
A26: Endpoint management (MDM) + password manager | C26: 300 | D26: Laptops are in scope for SOC 2.
A27: E-signature, email, productivity suite | C27: 300
A28: SaaS tooling total | C28: =SUM(C21:C27) -> 3800

Sheet Staffing
A1: Team plans (loaded monthly cost = salary x ~1.25 / 12)
A2: Pick the plan in Assumptions. Support reps scale with accounts and are in COGS.
A4: Role | C4: Full: $ / month | D4: Full: start month | E4: Lean: $ / month | F4: Lean: start month | G4: Note
A5: Founder / CEO | C5: 12500 | D5: 1 | E5: 12500 | F5: 13 | G5: Lean: unpaid for the first 12 months.
A6: Founding AI / full-stack engineer | C6: 22000 | D6: 1 | E6: 22000 | F6: 1 | G6: ~$210k x 1.25 burden.
A7: Full-stack engineer | C7: 18000 | D7: 1 | E7: 18000 | F7: 7
A8: Commercial lending SME / product lead | C8: 9000 | D8: 1 | E8: 4500 | F8: 1 | G8: Ex-broker or credit officer; builds lender-ready package templates, grades agent output. Lean: half-time contractor.
A9: DevSecOps / security engineer | C9: 19000 | D9: 4 | E9: 6000 | F9: 3 | G9: Owns SOC 2 controls + infra. Lean: fractional contractor.
A10: Account executive (base + commission) | C10: 13000 | D10: 7 | E10: 13000 | F10: 10
A11: Marketing manager | C11: 11000 | D11: 10 | E11: 11000 | F11: 19
A12: Engineer #3 | C12: 18000 | D12: 13 | E12: 18000 | F12: 16
A13: Compliance & operations manager | C13: 12000 | D13: 16 | E13: 12000 | F13: 25 | G13: Security questionnaires, audits.
A14: Account executive #2 | C14: 13000 | D14: 16 | E14: 13000 | F14: 22
A15: Engineer #4 | C15: 18000 | D15: 19 | E15: 18000 | F15: 28

Sheet Setup
A1: One-time setup costs
A2: Month = when the cost is paid. Estimates; get quotes.
A4: Item | C4: Cost ($) | D4: Month
A5: Entity formation, founder/IP agreements, cap table | C5: 6000 | D5: 1
A6: Regulatory counsel: lending/broker licensing, ECOA/Reg B, UPL, state law memo | C6: 25000 | D6: 1
A7: Terms of service, DPA, privacy policy, AI-use disclosures, MSA template | C7: 12000 | D7: 2
A8: Trademark search and filing | C8: 3000 | D8: 2
A9: Brand, website, product design system | C9: 25000 | D9: 2
A10: Lending template library: credit memo, spreading, policy packs (SME time) | C10: 15000 | D10: 3
A11: Evaluation dataset: synthetic loan packages + expert grading | C11: 15000 | D11: 4
A12: Laptops and equipment (5) | C12: 15000 | D12: 1
A13: SOC 2 readiness consultant | C13: 15000 | D13: 4
A14: SOC 2 Type I audit | C14: 20000 | D14: 6
A15: Independent penetration test before launch | C15: 18000 | D15: 6
A16: Launch marketing: conferences, association sponsorships, collateral | C16: 15000 | D16: 6
A17: Contingency (% of items above) | B17: 0.15 | C17: =SUM(C5:C16)*B17 -> 27600 | D17: 1
A18: Total one-time setup | C18: =SUM(C5:C17) -> 211600

Sheet Monthly
A1: 36-month operating model ($)
A2: All cells are formulas over the input sheets.
B4: Month | C4: 1 | D4: 2 | E4: 3 | F4: 4 | G4: 5 | H4: 6 | I4: 7 | J4: 8 | K4: 9 | L4: 10 | M4: 11 | N4: 12 | O4: 13 | P4: 14 | Q4: 15 | R4: 16 | S4: 17 | T4: 18 | U4: 19 | V4: 20 | W4: 21 | X4: 22 | Y4: 23 | Z4: 24 | AA4: 25 | AB4: 26 | AC4: 27 | AD4: 28 | AE4: 29 | AF4: 30 | AG4: 31 | AH4: 32 | AI4: 33 | AJ4: 34 | AK4: 35 | AL4: 36
B5: Year | C5: =ROUNDUP(C4/12,0) -> 1 | D5: =ROUNDUP(D4/12,0) -> 1 | E5: =ROUNDUP(E4/12,0) -> 1 | F5: =ROUNDUP(F4/12,0) -> 1 | G5: =ROUNDUP(G4/12,0) -> 1 | H5: =ROUNDUP(H4/12,0) -> 1 | I5: =ROUNDUP(I4/12,0) -> 1 | J5: =ROUNDUP(J4/12,0) -> 1 | ... AL5: =ROUNDUP(AL4/12,0) -> 3
B6: Live (1 = selling) | C6: =IF(C4>=Assumptions!$F$7,1,0) -> 0 | D6: =IF(D4>=Assumptions!$F$7,1,0) -> 0 | E6: =IF(E4>=Assumptions!$F$7,1,0) -> 0 | F6: =IF(F4>=Assumptions!$F$7,1,0) -> 0 | G6: =IF(G4>=Assumptions!$F$7,1,0) -> 0 | H6: =IF(H4>=Assumptions!$F$7,1,0) -> 0 | I6: =IF(I4>=Assumptions!$F$7,1,0) -> 1 | J6: =IF(J4>=Assumptions!$F$7,1,0) -> 1 | ... AL6: =IF(AL4>=Assumptions!$F$7,1,0) -> 1
B8: Beginning accounts | C8: =0 -> 0 | D8: =C11 -> 0 | E8: =D11 -> 0 | F8: =E11 -> 0 | G8: =F11 -> 0 | H8: =G11 -> 0 | I8: =H11 -> 0 | J8: =I11 -> 6 | K8: =J11 -> 12.33 | ... AL8: =AK11 -> 504.99392
B9: New accounts | C9: =IF(C6=1,MIN(Assumptions!$F$11,Assumptions!$F$9*(1+Assumptions!$F$10)^(C4-Assumptions!$F$7)),0) -> 0 | D9: =IF(D6=1,MIN(Assumptions!$F$11,Assumptions!$F$9*(1+Assumptions!$F$10)^(D4-Assumptions!$F$7)),0) -> 0 | E9: =IF(E6=1,MIN(Assumptions!$F$11,Assumptions!$F$9*(1+Assumptions!$F$10)^(E4-Assumptions!$F$7)),0) -> 0 | F9: =IF(F6=1,MIN(Assumptions!$F$11,Assumptions!$F$9*(1+Assumptions!$F$10)^(F4-Assumptions!$F$7)),0) -> 0 | G9: =IF(G6=1,MIN(Assumptions!$F$11,Assumptions!$F$9*(1+Assumptions!$F$10)^(G4-Assumptions!$F$7)),0) -> 0 | H9: =IF(H6=1,MIN(Assumptions!$F$11,Assumptions!$F$9*(1+Assumptions!$F$10)^(H4-Assumptions!$F$7)),0) -> 0 | I9: =IF(I6=1,MIN(Assumptions!$F$11,Assumptions!$F$9*(1+Assumptions!$F$10)^(I4-Assumptions!$F$7)),0) -> 6 | J9: =IF(J6=1,MIN(Assumptions!$F$11,Assumptions!$F$9*(1+Assumptions!$F$10)^(J4-Assumptions!$F$7)),0) -> 6.48 | ... AL9: =IF(AL6=1,MIN(Assumptions!$F$11,Assumptions!$F$9*(1+Assumptions!$F$10)^(AL4-Assumptions!$F$7)),0) -> 55.903649
B10: Churned accounts | C10: =C8*Assumptions!$F$12 -> 0 | D10: =D8*Assumptions!$F$12 -> 0 | E10: =E8*Assumptions!$F$12 -> 0 | F10: =F8*Assumptions!$F$12 -> 0 | G10: =G8*Assumptions!$F$12 -> 0 | H10: =H8*Assumptions!$F$12 -> 0 | I10: =I8*Assumptions!$F$12 -> 0 | J10: =J8*Assumptions!$F$12 -> 0.15 | ... AL10: =AL8*Assumptions!$F$12 -> 12.624848
B11: Ending accounts | C11: =C8+C9-C10 -> 0 | D11: =D8+D9-D10 -> 0 | E11: =E8+E9-E10 -> 0 | F11: =F8+F9-F10 -> 0 | G11: =G8+G9-G10 -> 0 | H11: =H8+H9-H10 -> 0 | I11: =I8+I9-I10 -> 6 | J11: =J8+J9-J10 -> 12.33 | ... AL11: =AL8+AL9-AL10 -> 548.27272
B12: Seats | C12: =C11*Pricing!$C$27 -> 0 | D12: =D11*Pricing!$C$27 -> 0 | E12: =E11*Pricing!$C$27 -> 0 | F12: =F11*Pricing!$C$27 -> 0 | G12: =G11*Pricing!$C$27 -> 0 | H12: =H11*Pricing!$C$27 -> 0 | I12: =I11*Pricing!$C$27 -> 18.9 | J12: =J11*Pricing!$C$27 -> 38.8395 | ... AL12: =AL11*Pricing!$C$27 -> 1727.0591
B14: Subscription revenue | C14: =C11*Pricing!$C$26 -> 0 | D14: =D11*Pricing!$C$26 -> 0 | E14: =E11*Pricing!$C$26 -> 0 | F14: =F11*Pricing!$C$26 -> 0 | G14: =G11*Pricing!$C$26 -> 0 | H14: =H11*Pricing!$C$26 -> 0 | I14: =I11*Pricing!$C$26 -> 8544 | J14: =J11*Pricing!$C$26 -> 17557.92 | ... AL14: =AL11*Pricing!$C$26 -> 780740.35
B15: Onboarding fees | C15: =C9*Pricing!$C$28 -> 0 | D15: =D9*Pricing!$C$28 -> 0 | E15: =E9*Pricing!$C$28 -> 0 | F15: =F9*Pricing!$C$28 -> 0 | G15: =G9*Pricing!$C$28 -> 0 | H15: =H9*Pricing!$C$28 -> 0 | I15: =I9*Pricing!$C$28 -> 3450 | J15: =J9*Pricing!$C$28 -> 3726 | ... AL15: =AL9*Pricing!$C$28 -> 32144.598
B16: Total revenue | C16: =C14+C15 -> 0 | D16: =D14+D15 -> 0 | E16: =E14+E15 -> 0 | F16: =F14+F15 -> 0 | G16: =G14+G15 -> 0 | H16: =H14+H15 -> 0 | I16: =I14+I15 -> 11994 | J16: =J14+J15 -> 21283.92 | ... AL16: =AL14+AL15 -> 812884.95
B18: AI model usage (Claude) | C18: =C12*(Assumptions!$F$18*UnitCosts!$C$36+UnitCosts!$C$37) -> 0 | D18: =D12*(Assumptions!$F$18*UnitCosts!$C$36+UnitCosts!$C$37) -> 0 | E18: =E12*(Assumptions!$F$18*UnitCosts!$C$36+UnitCosts!$C$37) -> 0 | F18: =F12*(Assumptions!$F$18*UnitCosts!$C$36+UnitCosts!$C$37) -> 0 | G18: =G12*(Assumptions!$F$18*UnitCosts!$C$36+UnitCosts!$C$37) -> 0 | H18: =H12*(Assumptions!$F$18*UnitCosts!$C$36+UnitCosts!$C$37) -> 0 | I18: =I12*(Assumptions!$F$18*UnitCosts!$C$36+UnitCosts!$C$37) -> 972.3105 | J18: =J12*(Assumptions!$F$18*UnitCosts!$C$36+UnitCosts!$C$37) -> 1998.0981 | ... AL18: =AL12*(Assumptions!$F$18*UnitCosts!$C$36+UnitCosts!$C$37) -> 88848.554
B19: Document OCR | C19: =C12*Assumptions!$F$18*UnitCosts!$C$28 -> 0 | D19: =D12*Assumptions!$F$18*UnitCosts!$C$28 -> 0 | E19: =E12*Assumptions!$F$18*UnitCosts!$C$28 -> 0 | F19: =F12*Assumptions!$F$18*UnitCosts!$C$28 -> 0 | G19: =G12*Assumptions!$F$18*UnitCosts!$C$28 -> 0 | H19: =H12*Assumptions!$F$18*UnitCosts!$C$28 -> 0 | I19: =I12*Assumptions!$F$18*UnitCosts!$C$28 -> 226.8 | J19: =J12*Assumptions!$F$18*UnitCosts!$C$28 -> 466.074 | ... AL19: =AL12*Assumptions!$F$18*UnitCosts!$C$28 -> 20724.709
B20: Hosting baseline (servers) | C20: =IF(C4>=Assumptions!$F$7-1,Infrastructure!$C$18,Infrastructure!$C$18*Assumptions!$F$29) -> 1180 | D20: =IF(D4>=Assumptions!$F$7-1,Infrastructure!$C$18,Infrastructure!$C$18*Assumptions!$F$29) -> 1180 | E20: =IF(E4>=Assumptions!$F$7-1,Infrastructure!$C$18,Infrastructure!$C$18*Assumptions!$F$29) -> 1180 | F20: =IF(F4>=Assumptions!$F$7-1,Infrastructure!$C$18,Infrastructure!$C$18*Assumptions!$F$29) -> 1180 | G20: =IF(G4>=Assumptions!$F$7-1,Infrastructure!$C$18,Infrastructure!$C$18*Assumptions!$F$29) -> 1180 | H20: =IF(H4>=Assumptions!$F$7-1,Infrastructure!$C$18,Infrastructure!$C$18*Assumptions!$F$29) -> 2950 | I20: =IF(I4>=Assumptions!$F$7-1,Infrastructure!$C$18,Infrastructure!$C$18*Assumptions!$F$29) -> 2950 | J20: =IF(J4>=Assumptions!$F$7-1,Infrastructure!$C$18,Infrastructure!$C$18*Assumptions!$F$29) -> 2950 | ... AL20: =IF(AL4>=Assumptions!$F$7-1,Infrastructure!$C$18,Infrastructure!$C$18*Assumptions!$F$29) -> 2950
B21: Hosting variable + tenant keys | C21: =C12*Assumptions!$F$27+C11*Assumptions!$F$28 -> 0 | D21: =D12*Assumptions!$F$27+D11*Assumptions!$F$28 -> 0 | E21: =E12*Assumptions!$F$27+E11*Assumptions!$F$28 -> 0 | F21: =F12*Assumptions!$F$27+F11*Assumptions!$F$28 -> 0 | G21: =G12*Assumptions!$F$27+G11*Assumptions!$F$28 -> 0 | H21: =H12*Assumptions!$F$27+H11*Assumptions!$F$28 -> 0 | I21: =I12*Assumptions!$F$27+I11*Assumptions!$F$28 -> 232.8 | J21: =J12*Assumptions!$F$27+J11*Assumptions!$F$28 -> 478.404 | ... AL21: =AL12*Assumptions!$F$27+AL11*Assumptions!$F$28 -> 21272.982
B22: Payment processing | C22: =C16*Assumptions!$F$26 -> 0 | D22: =D16*Assumptions!$F$26 -> 0 | E22: =E16*Assumptions!$F$26 -> 0 | F22: =F16*Assumptions!$F$26 -> 0 | G22: =G16*Assumptions!$F$26 -> 0 | H22: =H16*Assumptions!$F$26 -> 0 | I22: =I16*Assumptions!$F$26 -> 347.826 | J22: =J16*Assumptions!$F$26 -> 617.23368 | ... AL22: =AL16*Assumptions!$F$26 -> 23573.664
B23: Customer support staff | C23: =IF(C6=1,MAX(1,ROUNDUP(C11/Assumptions!$F$20,0))*Assumptions!$F$24,0) -> 0 | D23: =IF(D6=1,MAX(1,ROUNDUP(D11/Assumptions!$F$20,0))*Assumptions!$F$24,0) -> 0 | E23: =IF(E6=1,MAX(1,ROUNDUP(E11/Assumptions!$F$20,0))*Assumptions!$F$24,0) -> 0 | F23: =IF(F6=1,MAX(1,ROUNDUP(F11/Assumptions!$F$20,0))*Assumptions!$F$24,0) -> 0 | G23: =IF(G6=1,MAX(1,ROUNDUP(G11/Assumptions!$F$20,0))*Assumptions!$F$24,0) -> 0 | H23: =IF(H6=1,MAX(1,ROUNDUP(H11/Assumptions!$F$20,0))*Assumptions!$F$24,0) -> 0 | I23: =IF(I6=1,MAX(1,ROUNDUP(I11/Assumptions!$F$20,0))*Assumptions!$F$24,0) -> 8500 | J23: =IF(J6=1,MAX(1,ROUNDUP(J11/Assumptions!$F$20,0))*Assumptions!$F$24,0) -> 8500 | ... AL23: =IF(AL6=1,MAX(1,ROUNDUP(AL11/Assumptions!$F$20,0))*Assumptions!$F$24,0) -> 85000
B24: Total cost of revenue | C24: =SUM(C18:C23) -> 1180 | D24: =SUM(D18:D23) -> 1180 | E24: =SUM(E18:E23) -> 1180 | F24: =SUM(F18:F23) -> 1180 | G24: =SUM(G18:G23) -> 1180 | H24: =SUM(H18:H23) -> 2950 | I24: =SUM(I18:I23) -> 13229.737 | J24: =SUM(J18:J23) -> 15009.81 | ... AL24: =SUM(AL18:AL23) -> 242369.91
B25: Gross profit | C25: =C16-C24 -> -1180 | D25: =D16-D24 -> -1180 | E25: =E16-E24 -> -1180 | F25: =F16-F24 -> -1180 | G25: =G16-G24 -> -1180 | H25: =H16-H24 -> -2950 | I25: =I16-I24 -> -1235.7365 | J25: =J16-J24 -> 6274.1102 | ... AL25: =AL16-AL24 -> 570515.04
B26: Gross margin % | C26: =IFERROR(C25/C16,0) -> 0 | D26: =IFERROR(D25/D16,0) -> 0 | E26: =IFERROR(E25/E16,0) -> 0 | F26: =IFERROR(F25/F16,0) -> 0 | G26: =IFERROR(G25/G16,0) -> 0 | H26: =IFERROR(H25/H16,0) -> 0 | I26: =IFERROR(I25/I16,0) -> -0.10302956 | J26: =IFERROR(J25/J16,0) -> 0.29478171 | ... AL26: =IFERROR(AL25/AL16,0) -> 0.70183984
B28: Payroll (product, engineering, sales, G&A) | C28: =IF(Assumptions!$F$34=1,SUMPRODUCT((Staffing!$D$5:$D$15<=C4)*Staffing!$C$5:$C$15),SUMPRODUCT((Staffing!$F$5:$F$15<=C4)*Staffing!$E$5:$E$15)) -> 61500 | D28: =IF(Assumptions!$F$34=1,SUMPRODUCT((Staffing!$D$5:$D$15<=D4)*Staffing!$C$5:$C$15),SUMPRODUCT((Staffing!$F$5:$F$15<=D4)*Staffing!$E$5:$E$15)) -> 61500 | E28: =IF(Assumptions!$F$34=1,SUMPRODUCT((Staffing!$D$5:$D$15<=E4)*Staffing!$C$5:$C$15),SUMPRODUCT((Staffing!$F$5:$F$15<=E4)*Staffing!$E$5:$E$15)) -> 61500 | F28: =IF(Assumptions!$F$34=1,SUMPRODUCT((Staffing!$D$5:$D$15<=F4)*Staffing!$C$5:$C$15),SUMPRODUCT((Staffing!$F$5:$F$15<=F4)*Staffing!$E$5:$E$15)) -> 80500 | G28: =IF(Assumptions!$F$34=1,SUMPRODUCT((Staffing!$D$5:$D$15<=G4)*Staffing!$C$5:$C$15),SUMPRODUCT((Staffing!$F$5:$F$15<=G4)*Staffing!$E$5:$E$15)) -> 80500 | H28: =IF(Assumptions!$F$34=1,SUMPRODUCT((Staffing!$D$5:$D$15<=H4)*Staffing!$C$5:$C$15),SUMPRODUCT((Staffing!$F$5:$F$15<=H4)*Staffing!$E$5:$E$15)) -> 80500 | I28: =IF(Assumptions!$F$34=1,SUMPRODUCT((Staffing!$D$5:$D$15<=I4)*Staffing!$C$5:$C$15),SUMPRODUCT((Staffing!$F$5:$F$15<=I4)*Staffing!$E$5:$E$15)) -> 93500 | J28: =IF(Assumptions!$F$34=1,SUMPRODUCT((Staffing!$D$5:$D$15<=J4)*Staffing!$C$5:$C$15),SUMPRODUCT((Staffing!$F$5:$F$15<=J4)*Staffing!$E$5:$E$15)) -> 93500 | ... AL28: =IF(Assumptions!$F$34=1,SUMPRODUCT((Staffing!$D$5:$D$15<=AL4)*Staffing!$C$5:$C$15),SUMPRODUCT((Staffing!$F$5:$F$15<=AL4)*Staffing!$E$5:$E$15)) -> 165500
B29: Sales & marketing (CAC + base) | C29: =C9*Assumptions!$F$21+IF(C4>=Assumptions!$F$7-2,Assumptions!$F$25,0) -> 0 | D29: =D9*Assumptions!$F$21+IF(D4>=Assumptions!$F$7-2,Assumptions!$F$25,0) -> 0 | E29: =E9*Assumptions!$F$21+IF(E4>=Assumptions!$F$7-2,Assumptions!$F$25,0) -> 0 | F29: =F9*Assumptions!$F$21+IF(F4>=Assumptions!$F$7-2,Assumptions!$F$25,0) -> 0 | G29: =G9*Assumptions!$F$21+IF(G4>=Assumptions!$F$7-2,Assumptions!$F$25,0) -> 5000 | H29: =H9*Assumptions!$F$21+IF(H4>=Assumptions!$F$7-2,Assumptions!$F$25,0) -> 5000 | I29: =I9*Assumptions!$F$21+IF(I4>=Assumptions!$F$7-2,Assumptions!$F$25,0) -> 29000 | J29: =J9*Assumptions!$F$21+IF(J4>=Assumptions!$F$7-2,Assumptions!$F$25,0) -> 30920 | ... AL29: =AL9*Assumptions!$F$21+IF(AL4>=Assumptions!$F$7-2,Assumptions!$F$25,0) -> 228614.6
B30: Security & operations SaaS | C30: =Infrastructure!$C$28 -> 3800 | D30: =Infrastructure!$C$28 -> 3800 | E30: =Infrastructure!$C$28 -> 3800 | F30: =Infrastructure!$C$28 -> 3800 | G30: =Infrastructure!$C$28 -> 3800 | H30: =Infrastructure!$C$28 -> 3800 | I30: =Infrastructure!$C$28 -> 3800 | J30: =Infrastructure!$C$28 -> 3800 | ... AL30: =Infrastructure!$C$28 -> 3800
B31: Insurance | C31: =Assumptions!$F$30 -> 2500 | D31: =Assumptions!$F$30 -> 2500 | E31: =Assumptions!$F$30 -> 2500 | F31: =Assumptions!$F$30 -> 2500 | G31: =Assumptions!$F$30 -> 2500 | H31: =Assumptions!$F$30 -> 2500 | I31: =Assumptions!$F$30 -> 2500 | J31: =Assumptions!$F$30 -> 2500 | ... AL31: =Assumptions!$F$30 -> 2500
B32: Professional services | C32: =Assumptions!$F$31 -> 4500 | D32: =Assumptions!$F$31 -> 4500 | E32: =Assumptions!$F$31 -> 4500 | F32: =Assumptions!$F$31 -> 4500 | G32: =Assumptions!$F$31 -> 4500 | H32: =Assumptions!$F$31 -> 4500 | I32: =Assumptions!$F$31 -> 4500 | J32: =Assumptions!$F$31 -> 4500 | ... AL32: =Assumptions!$F$31 -> 4500
B33: Recurring compliance (SOC 2 Type II, pen tests) | C33: =IF(C4>=Assumptions!$F$33,Assumptions!$F$32,0) -> 0 | D33: =IF(D4>=Assumptions!$F$33,Assumptions!$F$32,0) -> 0 | E33: =IF(E4>=Assumptions!$F$33,Assumptions!$F$32,0) -> 0 | F33: =IF(F4>=Assumptions!$F$33,Assumptions!$F$32,0) -> 0 | G33: =IF(G4>=Assumptions!$F$33,Assumptions!$F$32,0) -> 0 | H33: =IF(H4>=Assumptions!$F$33,Assumptions!$F$32,0) -> 0 | I33: =IF(I4>=Assumptions!$F$33,Assumptions!$F$32,0) -> 0 | J33: =IF(J4>=Assumptions!$F$33,Assumptions!$F$32,0) -> 0 | ... AL33: =IF(AL4>=Assumptions!$F$33,Assumptions!$F$32,0) -> 5000
B34: Other G&A | C34: =Assumptions!$F$35 -> 3000 | D34: =Assumptions!$F$35 -> 3000 | E34: =Assumptions!$F$35 -> 3000 | F34: =Assumptions!$F$35 -> 3000 | G34: =Assumptions!$F$35 -> 3000 | H34: =Assumptions!$F$35 -> 3000 | I34: =Assumptions!$F$35 -> 3000 | J34: =Assumptions!$F$35 -> 3000 | ... AL34: =Assumptions!$F$35 -> 3000
B35: One-time setup costs | C35: =SUMIF(Setup!$D$5:$D$17,C4,Setup!$C$5:$C$17) -> 73600 | D35: =SUMIF(Setup!$D$5:$D$17,D4,Setup!$C$5:$C$17) -> 40000 | E35: =SUMIF(Setup!$D$5:$D$17,E4,Setup!$C$5:$C$17) -> 15000 | F35: =SUMIF(Setup!$D$5:$D$17,F4,Setup!$C$5:$C$17) -> 30000 | G35: =SUMIF(Setup!$D$5:$D$17,G4,Setup!$C$5:$C$17) -> 0 | H35: =SUMIF(Setup!$D$5:$D$17,H4,Setup!$C$5:$C$17) -> 53000 | I35: =SUMIF(Setup!$D$5:$D$17,I4,Setup!$C$5:$C$17) -> 0 | J35: =SUMIF(Setup!$D$5:$D$17,J4,Setup!$C$5:$C$17) -> 0 | ... AL35: =SUMIF(Setup!$D$5:$D$17,AL4,Setup!$C$5:$C$17) -> 0
B36: Total operating expenses | C36: =SUM(C28:C35) -> 148900 | D36: =SUM(D28:D35) -> 115300 | E36: =SUM(E28:E35) -> 90300 | F36: =SUM(F28:F35) -> 124300 | G36: =SUM(G28:G35) -> 99300 | H36: =SUM(H28:H35) -> 152300 | I36: =SUM(I28:I35) -> 136300 | J36: =SUM(J28:J35) -> 138220 | ... AL36: =SUM(AL28:AL35) -> 412914.6
B38: EBITDA (monthly profit / loss) | C38: =C25-C36 -> -150080 | D38: =D25-D36 -> -116480 | E38: =E25-E36 -> -91480 | F38: =F25-F36 -> -125480 | G38: =G25-G36 -> -100480 | H38: =H25-H36 -> -155250 | I38: =I25-I36 -> -137535.74 | J38: =J25-J36 -> -131945.89 | ... AL38: =AL25-AL36 -> 157600.45
B39: Cumulative cash flow | C39: =C38 -> -150080 | D39: =C39+D38 -> -266560 | E39: =D39+E38 -> -358040 | F39: =E39+F38 -> -483520 | G39: =F39+G38 -> -584000 | H39: =G39+H38 -> -739250 | I39: =H39+I38 -> -876785.74 | J39: =I39+J38 -> -1008731.6 | K39: =J39+K38 -> -1134807.8 | ... AL39: =AK39+AL38 -> -2552947.9
B40: Total costs (COGS + opex) | C40: =C24+C36 -> 150080 | D40: =D24+D36 -> 116480 | E40: =E24+E36 -> 91480 | F40: =F24+F36 -> 125480 | G40: =G24+G36 -> 100480 | H40: =H24+H36 -> 155250 | I40: =I24+I36 -> 149529.74 | J40: =J24+J36 -> 153229.81 | ... AL40: =AL24+AL36 -> 655284.51
B42: helper: month if EBITDA-positive | C42: =IF(AND(C6=1,C38>0),C4,999) -> 999 | D42: =IF(AND(D6=1,D38>0),D4,999) -> 999 | E42: =IF(AND(E6=1,E38>0),E4,999) -> 999 | F42: =IF(AND(F6=1,F38>0),F4,999) -> 999 | G42: =IF(AND(G6=1,G38>0),G4,999) -> 999 | H42: =IF(AND(H6=1,H38>0),H4,999) -> 999 | I42: =IF(AND(I6=1,I38>0),I4,999) -> 999 | J42: =IF(AND(J6=1,J38>0),J4,999) -> 999 | ... AL42: =IF(AND(AL6=1,AL38>0),AL4,999) -> 36
B43: helper: month if cumulative cash recovered | C43: =IF(AND(C6=1,C39>=0),C4,999) -> 999 | D43: =IF(AND(D6=1,D39>=0),D4,999) -> 999 | E43: =IF(AND(E6=1,E39>=0),E4,999) -> 999 | F43: =IF(AND(F6=1,F39>=0),F4,999) -> 999 | G43: =IF(AND(G6=1,G39>=0),G4,999) -> 999 | H43: =IF(AND(H6=1,H39>=0),H4,999) -> 999 | I43: =IF(AND(I6=1,I39>=0),I4,999) -> 999 | J43: =IF(AND(J6=1,J39>=0),J4,999) -> 999 | ... AL43: =IF(AND(AL6=1,AL39>=0),AL4,999) -> 999
